Traceback (most recent call last):
  File "C:\Users\Desarrollador XPD\AppData\Local\Programs\Python\Python313\Lib\site-packages\jupyter_core\utils\__init__.py", line 154, in wrapped
    asyncio.get_running_loop()
    ~~~~~~~~~~~~~~~~~~~~~~~~^^
RuntimeError: no running event loop

During handling of the above exception, another exception occurred:

Traceback (most recent call last):
  File "C:\Users\Desarrollador XPD\AppData\Local\Programs\Python\Python313\Lib\site-packages\jupyter_cache\executors\utils.py", line 58, in single_nb_execution
    executenb(
    ~~~~~~~~~^
        nb,
        ^^^
    ...<4 lines>...
        **kwargs,
        ^^^^^^^^^
    )
    ^
  File "C:\Users\Desarrollador XPD\AppData\Local\Programs\Python\Python313\Lib\site-packages\nbclient\client.py", line 1319, in execute
    return NotebookClient(nb=nb, resources=resources, km=km, **kwargs).execute()
           ~~~~~~~~~~~~~~~~~~~~~~~~~~~~~~~~~~~~~~~~~~~~~~~~~~~~~~~~~~~~~~~~~~~^^
  File "C:\Users\Desarrollador XPD\AppData\Local\Programs\Python\Python313\Lib\site-packages\jupyter_core\utils\__init__.py", line 158, in wrapped
    return loop.run_until_complete(inner)
           ~~~~~~~~~~~~~~~~~~~~~~~^^^^^^^
  File "C:\Users\Desarrollador XPD\AppData\Local\Programs\Python\Python313\Lib\asyncio\base_events.py", line 725, in run_until_complete
    return future.result()
           ~~~~~~~~~~~~~^^
  File "C:\Users\Desarrollador XPD\AppData\Local\Programs\Python\Python313\Lib\site-packages\nbclient\client.py", line 709, in async_execute
    await self.async_execute_cell(
        cell, index, execution_count=self.code_cells_executed + 1
    )
  File "C:\Users\Desarrollador XPD\AppData\Local\Programs\Python\Python313\Lib\site-packages\nbclient\client.py", line 1062, in async_execute_cell
    await self._check_raise_for_error(cell, cell_index, exec_reply)
  File "C:\Users\Desarrollador XPD\AppData\Local\Programs\Python\Python313\Lib\site-packages\nbclient\client.py", line 918, in _check_raise_for_error
    raise CellExecutionError.from_cell_and_msg(cell, exec_reply_content)
nbclient.exceptions.CellExecutionError: An error occurred while executing the following cell:
------------------
import pyodbc
import numpy as np
import pandas as pd
import matplotlib.pyplot as plt
from statsmodels.tsa.stattools import adfuller, acf, pacf
from statsmodels.graphics.tsaplots import plot_acf, plot_pacf
from statsmodels.tsa.seasonal import seasonal_decompose
from statsmodels.tsa.arima_model import ARIMA

pd.options.display.float_format = '{:.2f}'.format
plt.rcParams['figure.figsize'] = [12, 8]

import warnings
warnings.filterwarnings('ignore')
------------------


[31m---------------------------------------------------------------------------[39m
[31mModuleNotFoundError[39m                       Traceback (most recent call last)
[36mCell[39m[36m [39m[32mIn[1][39m[32m, line 5[39m
[32m      3[39m [38;5;28;01mimport[39;00m[38;5;250m [39m[34;01mpandas[39;00m[38;5;250m [39m[38;5;28;01mas[39;00m[38;5;250m [39m[34;01mpd[39;00m
[32m      4[39m [38;5;28;01mimport[39;00m[38;5;250m [39m[34;01mmatplotlib[39;00m[34;01m.[39;00m[34;01mpyplot[39;00m[38;5;250m [39m[38;5;28;01mas[39;00m[38;5;250m [39m[34;01mplt[39;00m
[32m----> [39m[32m5[39m [38;5;28;01mfrom[39;00m[38;5;250m [39m[34;01mstatsmodels[39;00m[34;01m.[39;00m[34;01mtsa[39;00m[34;01m.[39;00m[34;01mstattools[39;00m[38;5;250m [39m[38;5;28;01mimport[39;00m adfuller, acf, pacf
[32m      6[39m [38;5;28;01mfrom[39;00m[38;5;250m [39m[34;01mstatsmodels[39;00m[34;01m.[39;00m[34;01mgraphics[39;00m[34;01m.[39;00m[34;01mtsaplots[39;00m[38;5;250m [39m[38;5;28;01mimport[39;00m plot_acf, plot_pacf
[32m      7[39m [38;5;28;01mfrom[39;00m[38;5;250m [39m[34;01mstatsmodels[39;00m[34;01m.[39;00m[34;01mtsa[39;00m[34;01m.[39;00m[34;01mseasonal[39;00m[38;5;250m [39m[38;5;28;01mimport[39;00m seasonal_decompose

[31mModuleNotFoundError[39m: No module named 'statsmodels'

